<?xml version="1.0" encoding="UTF-8"?>
<!-- Generated by org.testng.reporters.JUnitXMLReporter -->
<testsuite ignored="0" hostname="Rahee-Khan" failures="1" tests="1" name="Test_E2E_02_iOS" time="77.945" errors="0" timestamp="2023-11-13T16:42:53 EST">
  <testcase classname="base.MobileDeviceDriver" name="@BeforeMethod setUp" time="46.251">
    <failure type="org.openqa.selenium.SessionNotCreatedException" message="Could not start a new session. Response code 500. Message: An unknown server-side error occurred while processing the command. Original error: java.net.ConnectException: Connection refused 
Host info: host: &amp;apos;Rahee-Khan&amp;apos;, ip: &amp;apos;fd41:8c9d:9153:c210:c8b:2aea:603c:3aaf%en0&amp;apos;
Build info: version: &amp;apos;4.15.0&amp;apos;, revision: &amp;apos;1d14b5521b&amp;apos;
System info: os.name: &amp;apos;Mac OS X&amp;apos;, os.arch: &amp;apos;x86_64&amp;apos;, os.version: &amp;apos;14.0&amp;apos;, java.version: &amp;apos;21.0.1&amp;apos;
Driver info: io.appium.java_client.ios.IOSDriver
Command: [null, newSession {capabilities=[{appium:accessKey=eyJhbGciOiJIUzI1NiJ9.eyJ4cC51Ijo5ODU3OTgwLCJ4cC5wIjoxMDk4NzU5NCwieHAubSI6MTY4OTA4MTQ5ODEzOSwiZXhwIjoyMDEwNTkwNTk4LCJpc3MiOiJjb20uZXhwZXJpdGVzdCJ9.ar3l55jlt470f5fb8CPpkFeJ_UaNQMfpzLEjmfjmyd0, appium:appiumVersion=2.1.3, appium:automationName=XCUITest, browserName=Safari, appium:deviceQuery=@os=&amp;apos;ios&amp;apos; and @category=&amp;apos;PHONE&amp;apos; and contains(@region, &amp;apos;US&amp;apos;), platformName=IOS, appium:testName=verify_user_making_payment}], desiredCapabilities=Capabilities {accessKey: eyJhbGciOiJIUzI1NiJ9.eyJ4cC..., appiumVersion: 2.1.3, automationName: XCUITest, browserName: Safari, deviceQuery: @os=&amp;apos;ios&amp;apos; and @category=&amp;apos;PH..., platformName: IOS, testName: verify_user_making_payment}}]
Capabilities {accessKey: eyJhbGciOiJIUzI1NiJ9.eyJ4cC..., appiumVersion: 2.1.3, automationName: XCUITest, browserName: Safari, deviceQuery: @os=&amp;apos;ios&amp;apos; and @category=&amp;apos;PH..., platformName: IOS, testName: verify_user_making_payment}">
      <![CDATA[org.openqa.selenium.SessionNotCreatedException: Could not start a new session. Response code 500. Message: An unknown server-side error occurred while processing the command. Original error: java.net.ConnectException: Connection refused 
Host info: host: 'Rahee-Khan', ip: 'fd41:8c9d:9153:c210:c8b:2aea:603c:3aaf%en0'
Build info: version: '4.15.0', revision: '1d14b5521b'
System info: os.name: 'Mac OS X', os.arch: 'x86_64', os.version: '14.0', java.version: '21.0.1'
Driver info: io.appium.java_client.ios.IOSDriver
Command: [null, newSession {capabilities=[{appium:accessKey=eyJhbGciOiJIUzI1NiJ9.eyJ4cC51Ijo5ODU3OTgwLCJ4cC5wIjoxMDk4NzU5NCwieHAubSI6MTY4OTA4MTQ5ODEzOSwiZXhwIjoyMDEwNTkwNTk4LCJpc3MiOiJjb20uZXhwZXJpdGVzdCJ9.ar3l55jlt470f5fb8CPpkFeJ_UaNQMfpzLEjmfjmyd0, appium:appiumVersion=2.1.3, appium:automationName=XCUITest, browserName=Safari, appium:deviceQuery=@os='ios' and @category='PHONE' and contains(@region, 'US'), platformName=IOS, appium:testName=verify_user_making_payment}], desiredCapabilities=Capabilities {accessKey: eyJhbGciOiJIUzI1NiJ9.eyJ4cC..., appiumVersion: 2.1.3, automationName: XCUITest, browserName: Safari, deviceQuery: @os='ios' and @category='PH..., platformName: IOS, testName: verify_user_making_payment}}]
Capabilities {accessKey: eyJhbGciOiJIUzI1NiJ9.eyJ4cC..., appiumVersion: 2.1.3, automationName: XCUITest, browserName: Safari, deviceQuery: @os='ios' and @category='PH..., platformName: IOS, testName: verify_user_making_payment}
at org.openqa.selenium.remote.ProtocolHandshake.createSession(ProtocolHandshake.java:140)
at io.appium.java_client.remote.AppiumProtocolHandshake.createSession(AppiumProtocolHandshake.java:133)
at io.appium.java_client.remote.AppiumProtocolHandshake.createSession(AppiumProtocolHandshake.java:102)
at io.appium.java_client.remote.AppiumCommandExecutor.createSession(AppiumCommandExecutor.java:194)
at io.appium.java_client.remote.AppiumCommandExecutor.execute(AppiumCommandExecutor.java:262)
at org.openqa.selenium.remote.RemoteWebDriver.execute(RemoteWebDriver.java:531)
at io.appium.java_client.AppiumDriver.startSession(AppiumDriver.java:229)
at org.openqa.selenium.remote.RemoteWebDriver.<init>(RemoteWebDriver.java:154)
at io.appium.java_client.AppiumDriver.<init>(AppiumDriver.java:80)
at io.appium.java_client.AppiumDriver.<init>(AppiumDriver.java:92)
at io.appium.java_client.ios.IOSDriver.<init>(IOSDriver.java:106)
at base.MobileDeviceDriver.setUp(MobileDeviceDriver.java:52)
at java.base/java.util.ArrayList.forEach(ArrayList.java:1596)
at java.base/java.util.concurrent.FutureTask.run(FutureTask.java:317)
at java.base/java.util.concurrent.ThreadPoolExecutor.runWorker(ThreadPoolExecutor.java:1144)
at java.base/java.util.concurrent.ThreadPoolExecutor$Worker.run(ThreadPoolExecutor.java:642)
at java.base/java.lang.Thread.run(Thread.java:1583)
... Removed 22 stack frames]]>
    </failure>
  </testcase> <!-- @BeforeMethod setUp -->
  <testcase classname="base.MobileDeviceDriver" name="@AfterMethod tearDown" time="0.001">
    <failure type="java.lang.NullPointerException" message="Cannot invoke &amp;quot;org.openqa.selenium.remote.RemoteWebDriver.quit()&amp;quot; because the return value of &amp;quot;base.MobileDeviceDriver.getDriver()&amp;quot; is null">
      <![CDATA[java.lang.NullPointerException: Cannot invoke "org.openqa.selenium.remote.RemoteWebDriver.quit()" because the return value of "base.MobileDeviceDriver.getDriver()" is null
at base.MobileDeviceDriver.tearDown(MobileDeviceDriver.java:82)
at java.base/java.util.ArrayList.forEach(ArrayList.java:1596)
at java.base/java.util.concurrent.FutureTask.run(FutureTask.java:317)
at java.base/java.util.concurrent.ThreadPoolExecutor.runWorker(ThreadPoolExecutor.java:1144)
at java.base/java.util.concurrent.ThreadPoolExecutor$Worker.run(ThreadPoolExecutor.java:642)
at java.base/java.lang.Thread.run(Thread.java:1583)
... Removed 21 stack frames]]>
    </failure>
  </testcase> <!-- @AfterMethod tearDown -->
  <testcase classname="mobile_tests.BankingApplicationPaymentTests" name="verify_user_making_payment" time="19.982">
    <failure type="java.lang.AssertionError" message="Amount has not been deducted. did not expect [35000] but found [35000]">
      <![CDATA[java.lang.AssertionError: Amount has not been deducted. did not expect [35000] but found [35000]
at mobile_tests.BankingApplicationPaymentTests.verify_user_making_payment(BankingApplicationPaymentTests.java:86)
at java.base/java.util.ArrayList.forEach(ArrayList.java:1596)
at java.base/java.util.concurrent.FutureTask.run(FutureTask.java:317)
at java.base/java.util.concurrent.ThreadPoolExecutor.runWorker(ThreadPoolExecutor.java:1144)
at java.base/java.util.concurrent.ThreadPoolExecutor$Worker.run(ThreadPoolExecutor.java:642)
at java.base/java.lang.Thread.run(Thread.java:1583)
... Removed 20 stack frames]]>
    </failure>
  </testcase> <!-- verify_user_making_payment -->
</testsuite> <!-- Test_E2E_02_iOS -->
