<?xml version="1.0" encoding="UTF-8"?>
<!-- Generated by org.testng.reporters.JUnitReportReporter -->
<testsuite hostname="Rahee-Khan" failures="3" tests="14" name="mobile_tests.PaymentTests" time="4421.935" errors="4" timestamp="2023-11-16T18:58:40 EST" skipped="2">
  <testcase classname="mobile_tests.PaymentTests" name="setUp" time="240.672">
    <error message="Could not start a new session. Response code 500. Message: Failed to prepare the Appium OSS Infrastructure: runWDA &gt; Cannot start run_wda after 120 retries : java.util.concurrent.ExecutionException - java.net.ConnectException: Failed to connect - received number 3, link:https://uscloud.experitest.com:443/reporter/#/test/1075/project/Art Of Testing - OSS/ 
Host info: host: &#039;Rahee-Khan&#039;, ip: &#039;fd41:8c9d:9153:c210:c8b:2aea:603c:3aaf%en0&#039;
Build info: version: &#039;4.15.0&#039;, revision: &#039;1d14b5521b&#039;
System info: os.name: &#039;Mac OS X&#039;, os.arch: &#039;x86_64&#039;, os.version: &#039;14.0&#039;, java.version: &#039;21.0.1&#039;
Driver info: io.appium.java_client.ios.IOSDriver
Command: [null, newSession {capabilities=[{appium:accessKey=eyJhbGciOiJIUzI1NiJ9.eyJ4cC51Ijo5ODU3OTgwLCJ4cC5wIjoxMDk4NzU5NCwieHAubSI6MTY4OTA4MTQ5ODEzOSwiZXhwIjoyMDEwNTkwNTk4LCJpc3MiOiJjb20uZXhwZXJpdGVzdCJ9.ar3l55jlt470f5fb8CPpkFeJ_UaNQMfpzLEjmfjmyd0, appium:appiumVersion=2.1.3, appium:automationName=XCUITest, browserName=Safari, appium:deviceQuery=@os=&#039;ios&#039; and @category=&#039;PHONE&#039; and contains(@region, &#039;US&#039;), platformName=IOS, appium:testName=verify_user_making_payment}], desiredCapabilities=Capabilities {accessKey: eyJhbGciOiJIUzI1NiJ9.eyJ4cC..., appiumVersion: 2.1.3, automationName: XCUITest, browserName: Safari, deviceQuery: @os=&#039;ios&#039; and @category=&#039;PH..., platformName: IOS, testName: verify_user_making_payment}}]
Capabilities {accessKey: eyJhbGciOiJIUzI1NiJ9.eyJ4cC..., appiumVersion: 2.1.3, automationName: XCUITest, browserName: Safari, deviceQuery: @os=&#039;ios&#039; and @category=&#039;PH..., platformName: IOS, testName: verify_user_making_payment}" type="org.openqa.selenium.SessionNotCreatedException">
      <![CDATA[org.openqa.selenium.SessionNotCreatedException: Could not start a new session. Response code 500. Message: Failed to prepare the Appium OSS Infrastructure: runWDA > Cannot start run_wda after 120 retries : java.util.concurrent.ExecutionException - java.net.ConnectException: Failed to connect - received number 3, link:https://uscloud.experitest.com:443/reporter/#/test/1075/project/Art Of Testing - OSS/ 
Host info: host: 'Rahee-Khan', ip: 'fd41:8c9d:9153:c210:c8b:2aea:603c:3aaf%en0'
Build info: version: '4.15.0', revision: '1d14b5521b'
System info: os.name: 'Mac OS X', os.arch: 'x86_64', os.version: '14.0', java.version: '21.0.1'
Driver info: io.appium.java_client.ios.IOSDriver
Command: [null, newSession {capabilities=[{appium:accessKey=eyJhbGciOiJIUzI1NiJ9.eyJ4cC51Ijo5ODU3OTgwLCJ4cC5wIjoxMDk4NzU5NCwieHAubSI6MTY4OTA4MTQ5ODEzOSwiZXhwIjoyMDEwNTkwNTk4LCJpc3MiOiJjb20uZXhwZXJpdGVzdCJ9.ar3l55jlt470f5fb8CPpkFeJ_UaNQMfpzLEjmfjmyd0, appium:appiumVersion=2.1.3, appium:automationName=XCUITest, browserName=Safari, appium:deviceQuery=@os='ios' and @category='PHONE' and contains(@region, 'US'), platformName=IOS, appium:testName=verify_user_making_payment}], desiredCapabilities=Capabilities {accessKey: eyJhbGciOiJIUzI1NiJ9.eyJ4cC..., appiumVersion: 2.1.3, automationName: XCUITest, browserName: Safari, deviceQuery: @os='ios' and @category='PH..., platformName: IOS, testName: verify_user_making_payment}}]
Capabilities {accessKey: eyJhbGciOiJIUzI1NiJ9.eyJ4cC..., appiumVersion: 2.1.3, automationName: XCUITest, browserName: Safari, deviceQuery: @os='ios' and @category='PH..., platformName: IOS, testName: verify_user_making_payment}
at org.openqa.selenium.remote.ProtocolHandshake.createSession(ProtocolHandshake.java:140)
at java.base/jdk.internal.reflect.DirectMethodHandleAccessor.invoke(DirectMethodHandleAccessor.java:103)
at java.base/java.lang.reflect.Method.invoke(Method.java:580)
at io.appium.java_client.remote.AppiumProtocolHandshake.createSession(AppiumProtocolHandshake.java:133)
at io.appium.java_client.remote.AppiumProtocolHandshake.createSession(AppiumProtocolHandshake.java:102)
at io.appium.java_client.remote.AppiumCommandExecutor.createSession(AppiumCommandExecutor.java:194)
at io.appium.java_client.remote.AppiumCommandExecutor.execute(AppiumCommandExecutor.java:262)
at org.openqa.selenium.remote.RemoteWebDriver.execute(RemoteWebDriver.java:531)
at io.appium.java_client.AppiumDriver.startSession(AppiumDriver.java:229)
at org.openqa.selenium.remote.RemoteWebDriver.<init>(RemoteWebDriver.java:154)
at io.appium.java_client.AppiumDriver.<init>(AppiumDriver.java:80)
at io.appium.java_client.AppiumDriver.<init>(AppiumDriver.java:92)
at io.appium.java_client.ios.IOSDriver.<init>(IOSDriver.java:106)
at base.MobileDeviceDriver.setUp(MobileDeviceDriver.java:52)
at java.base/jdk.internal.reflect.DirectMethodHandleAccessor.invoke(DirectMethodHandleAccessor.java:103)
at java.base/java.lang.reflect.Method.invoke(Method.java:580)
at org.testng.internal.MethodInvocationHelper.invokeMethod(MethodInvocationHelper.java:133)
at org.testng.internal.MethodInvocationHelper.invokeMethodConsideringTimeout(MethodInvocationHelper.java:62)
at org.testng.internal.ConfigInvoker.invokeConfigurationMethod(ConfigInvoker.java:385)
at org.testng.internal.ConfigInvoker.invokeConfigurations(ConfigInvoker.java:321)
at org.testng.internal.TestInvoker.runConfigMethods(TestInvoker.java:700)
at org.testng.internal.TestInvoker.invokeMethod(TestInvoker.java:527)
at org.testng.internal.TestInvoker.invokeTestMethod(TestInvoker.java:173)
at org.testng.internal.MethodRunner.runInSequence(MethodRunner.java:46)
at org.testng.internal.TestInvoker$MethodInvocationAgent.invoke(TestInvoker.java:824)
at org.testng.internal.TestInvoker.invokeTestMethods(TestInvoker.java:146)
at org.testng.internal.TestMethodWorker.invokeTestMethods(TestMethodWorker.java:146)
at org.testng.internal.TestMethodWorker.run(TestMethodWorker.java:128)
at java.base/java.util.ArrayList.forEach(ArrayList.java:1596)
at org.testng.TestRunner.privateRun(TestRunner.java:794)
at org.testng.TestRunner.run(TestRunner.java:596)
at org.testng.SuiteRunner.runTest(SuiteRunner.java:377)
at org.testng.SuiteRunner.access$000(SuiteRunner.java:28)
at org.testng.SuiteRunner$SuiteWorker.run(SuiteRunner.java:418)
at org.testng.internal.thread.ThreadUtil.lambda$execute$0(ThreadUtil.java:64)
at java.base/java.util.concurrent.FutureTask.run(FutureTask.java:317)
at java.base/java.util.concurrent.ThreadPoolExecutor.runWorker(ThreadPoolExecutor.java:1144)
at java.base/java.util.concurrent.ThreadPoolExecutor$Worker.run(ThreadPoolExecutor.java:642)
at java.base/java.lang.Thread.run(Thread.java:1583)
]]>
    </error>
  </testcase> <!-- setUp -->
  <system-out/>
  <testcase classname="mobile_tests.PaymentTests" name="verify_user_making_payment" time="49.962"/>
  <system-out/>
  <testcase classname="mobile_tests.PaymentTests" name="verify_user_making_payment" time="81.218">
    <failure message="Amount has not been deducted. did not expect [35000] but found [35000]" type="java.lang.AssertionError">
      <![CDATA[java.lang.AssertionError: Amount has not been deducted. did not expect [35000] but found [35000]
at org.testng.Assert.fail(Assert.java:99)
at org.testng.Assert.failEquals(Assert.java:1041)
at org.testng.Assert.assertNotEqualsImpl(Assert.java:147)
at org.testng.Assert.assertNotEquals(Assert.java:1531)
at mobile_tests.PaymentTests.verify_user_making_payment(PaymentTests.java:86)
at java.base/jdk.internal.reflect.DirectMethodHandleAccessor.invoke(DirectMethodHandleAccessor.java:103)
at java.base/java.lang.reflect.Method.invoke(Method.java:580)
at org.testng.internal.MethodInvocationHelper.invokeMethod(MethodInvocationHelper.java:133)
at org.testng.internal.TestInvoker.invokeMethod(TestInvoker.java:598)
at org.testng.internal.TestInvoker.invokeTestMethod(TestInvoker.java:173)
at org.testng.internal.MethodRunner.runInSequence(MethodRunner.java:46)
at org.testng.internal.TestInvoker$MethodInvocationAgent.invoke(TestInvoker.java:824)
at org.testng.internal.TestInvoker.invokeTestMethods(TestInvoker.java:146)
at org.testng.internal.TestMethodWorker.invokeTestMethods(TestMethodWorker.java:146)
at org.testng.internal.TestMethodWorker.run(TestMethodWorker.java:128)
at java.base/java.util.ArrayList.forEach(ArrayList.java:1596)
at org.testng.TestRunner.privateRun(TestRunner.java:794)
at org.testng.TestRunner.run(TestRunner.java:596)
at org.testng.SuiteRunner.runTest(SuiteRunner.java:377)
at org.testng.SuiteRunner.access$000(SuiteRunner.java:28)
at org.testng.SuiteRunner$SuiteWorker.run(SuiteRunner.java:418)
at org.testng.internal.thread.ThreadUtil.lambda$execute$0(ThreadUtil.java:64)
at java.base/java.util.concurrent.FutureTask.run(FutureTask.java:317)
at java.base/java.util.concurrent.ThreadPoolExecutor.runWorker(ThreadPoolExecutor.java:1144)
at java.base/java.util.concurrent.ThreadPoolExecutor$Worker.run(ThreadPoolExecutor.java:642)
at java.base/java.lang.Thread.run(Thread.java:1583)
]]>
    </failure>
  </testcase> <!-- verify_user_making_payment -->
  <system-out/>
  <testcase classname="mobile_tests.PaymentTests" name="tearDown" time="0.001">
    <error message="Cannot invoke &quot;org.openqa.selenium.remote.RemoteWebDriver.quit()&quot; because the return value of &quot;base.MobileDeviceDriver.getDriver()&quot; is null" type="java.lang.NullPointerException">
      <![CDATA[java.lang.NullPointerException: Cannot invoke "org.openqa.selenium.remote.RemoteWebDriver.quit()" because the return value of "base.MobileDeviceDriver.getDriver()" is null
at base.MobileDeviceDriver.tearDown(MobileDeviceDriver.java:82)
at java.base/jdk.internal.reflect.DirectMethodHandleAccessor.invoke(DirectMethodHandleAccessor.java:103)
at java.base/java.lang.reflect.Method.invoke(Method.java:580)
at org.testng.internal.MethodInvocationHelper.invokeMethod(MethodInvocationHelper.java:133)
at org.testng.internal.MethodInvocationHelper.invokeMethodConsideringTimeout(MethodInvocationHelper.java:62)
at org.testng.internal.ConfigInvoker.invokeConfigurationMethod(ConfigInvoker.java:385)
at org.testng.internal.ConfigInvoker.invokeConfigurations(ConfigInvoker.java:321)
at org.testng.internal.TestInvoker.runConfigMethods(TestInvoker.java:700)
at org.testng.internal.TestInvoker.runAfterGroupsConfigurations(TestInvoker.java:676)
at org.testng.internal.TestInvoker.invokeMethod(TestInvoker.java:546)
at org.testng.internal.TestInvoker.invokeTestMethod(TestInvoker.java:173)
at org.testng.internal.MethodRunner.runInSequence(MethodRunner.java:46)
at org.testng.internal.TestInvoker$MethodInvocationAgent.invoke(TestInvoker.java:824)
at org.testng.internal.TestInvoker.invokeTestMethods(TestInvoker.java:146)
at org.testng.internal.TestMethodWorker.invokeTestMethods(TestMethodWorker.java:146)
at org.testng.internal.TestMethodWorker.run(TestMethodWorker.java:128)
at java.base/java.util.ArrayList.forEach(ArrayList.java:1596)
at org.testng.TestRunner.privateRun(TestRunner.java:794)
at org.testng.TestRunner.run(TestRunner.java:596)
at org.testng.SuiteRunner.runTest(SuiteRunner.java:377)
at org.testng.SuiteRunner.access$000(SuiteRunner.java:28)
at org.testng.SuiteRunner$SuiteWorker.run(SuiteRunner.java:418)
at org.testng.internal.thread.ThreadUtil.lambda$execute$0(ThreadUtil.java:64)
at java.base/java.util.concurrent.FutureTask.run(FutureTask.java:317)
at java.base/java.util.concurrent.ThreadPoolExecutor.runWorker(ThreadPoolExecutor.java:1144)
at java.base/java.util.concurrent.ThreadPoolExecutor$Worker.run(ThreadPoolExecutor.java:642)
at java.base/java.lang.Thread.run(Thread.java:1583)
]]>
    </error>
  </testcase> <!-- tearDown -->
  <system-out/>
  <testcase classname="mobile_tests.PaymentTests" name="verify_user_making_payment" time="52.028"/>
  <system-out/>
  <testcase classname="mobile_tests.PaymentTests" name="verify_user_making_payment" time="60.308"/>
  <system-out/>
  <testcase classname="mobile_tests.PaymentTests" name="verify_user_making_payment" time="0.000">
    <skipped/>
  </testcase> <!-- verify_user_making_payment -->
  <system-out/>
  <testcase classname="mobile_tests.PaymentTests" name="verify_user_making_payment" time="0.000">
    <skipped/>
  </testcase> <!-- verify_user_making_payment -->
  <system-out/>
  <testcase classname="mobile_tests.PaymentTests" name="verify_user_making_payment" time="66.218"/>
  <system-out/>
  <testcase classname="mobile_tests.PaymentTests" name="setUp" time="3326.292">
    <error message="Could not start a new session. Possible causes are invalid address of the remote server or browser start-up failure. 
Host info: host: &#039;Rahee-Khan&#039;, ip: &#039;fd41:8c9d:9153:c210:c8b:2aea:603c:3aaf%en0&#039;" type="org.openqa.selenium.SessionNotCreatedException">
      <![CDATA[org.openqa.selenium.SessionNotCreatedException: Could not start a new session. Possible causes are invalid address of the remote server or browser start-up failure. 
Host info: host: 'Rahee-Khan', ip: 'fd41:8c9d:9153:c210:c8b:2aea:603c:3aaf%en0'
at org.openqa.selenium.remote.RemoteWebDriver.execute(RemoteWebDriver.java:549)
at io.appium.java_client.AppiumDriver.startSession(AppiumDriver.java:229)
at org.openqa.selenium.remote.RemoteWebDriver.<init>(RemoteWebDriver.java:154)
at io.appium.java_client.AppiumDriver.<init>(AppiumDriver.java:80)
at io.appium.java_client.AppiumDriver.<init>(AppiumDriver.java:92)
at io.appium.java_client.ios.IOSDriver.<init>(IOSDriver.java:106)
at base.MobileDeviceDriver.setUp(MobileDeviceDriver.java:52)
at java.base/jdk.internal.reflect.DirectMethodHandleAccessor.invoke(DirectMethodHandleAccessor.java:103)
at java.base/java.lang.reflect.Method.invoke(Method.java:580)
at org.testng.internal.MethodInvocationHelper.invokeMethod(MethodInvocationHelper.java:133)
at org.testng.internal.MethodInvocationHelper.invokeMethodConsideringTimeout(MethodInvocationHelper.java:62)
at org.testng.internal.ConfigInvoker.invokeConfigurationMethod(ConfigInvoker.java:385)
at org.testng.internal.ConfigInvoker.invokeConfigurations(ConfigInvoker.java:321)
at org.testng.internal.TestInvoker.runConfigMethods(TestInvoker.java:700)
at org.testng.internal.TestInvoker.invokeMethod(TestInvoker.java:527)
at org.testng.internal.TestInvoker.invokeTestMethod(TestInvoker.java:173)
at org.testng.internal.MethodRunner.runInSequence(MethodRunner.java:46)
at org.testng.internal.TestInvoker$MethodInvocationAgent.invoke(TestInvoker.java:824)
at org.testng.internal.TestInvoker.invokeTestMethods(TestInvoker.java:146)
at org.testng.internal.TestMethodWorker.invokeTestMethods(TestMethodWorker.java:146)
at org.testng.internal.TestMethodWorker.run(TestMethodWorker.java:128)
at java.base/java.util.ArrayList.forEach(ArrayList.java:1596)
at org.testng.TestRunner.privateRun(TestRunner.java:794)
at org.testng.TestRunner.run(TestRunner.java:596)
at org.testng.SuiteRunner.runTest(SuiteRunner.java:377)
at org.testng.SuiteRunner.access$000(SuiteRunner.java:28)
at org.testng.SuiteRunner$SuiteWorker.run(SuiteRunner.java:418)
at org.testng.internal.thread.ThreadUtil.lambda$execute$0(ThreadUtil.java:64)
at java.base/java.util.concurrent.FutureTask.run(FutureTask.java:317)
at java.base/java.util.concurrent.ThreadPoolExecutor.runWorker(ThreadPoolExecutor.java:1144)
at java.base/java.util.concurrent.ThreadPoolExecutor$Worker.run(ThreadPoolExecutor.java:642)
at java.base/java.lang.Thread.run(Thread.java:1583)
Caused by: org.openqa.selenium.WebDriverException: java.lang.reflect.InvocationTargetException
Build info: version: '4.15.0', revision: '1d14b5521b'
System info: os.name: 'Mac OS X', os.arch: 'x86_64', os.version: '14.0', java.version: '21.0.1'
Driver info: driver.version: MobileDeviceDriver
at io.appium.java_client.remote.AppiumProtocolHandshake.createSession(AppiumProtocolHandshake.java:137)
at io.appium.java_client.remote.AppiumProtocolHandshake.createSession(AppiumProtocolHandshake.java:102)
at io.appium.java_client.remote.AppiumCommandExecutor.createSession(AppiumCommandExecutor.java:194)
at io.appium.java_client.remote.AppiumCommandExecutor.execute(AppiumCommandExecutor.java:262)
at org.openqa.selenium.remote.RemoteWebDriver.execute(RemoteWebDriver.java:531)
... 31 more
Caused by: java.lang.reflect.InvocationTargetException
at java.base/jdk.internal.reflect.DirectMethodHandleAccessor.invoke(DirectMethodHandleAccessor.java:118)
at java.base/java.lang.reflect.Method.invoke(Method.java:580)
at io.appium.java_client.remote.AppiumProtocolHandshake.createSession(AppiumProtocolHandshake.java:133)
... 35 more
Caused by: org.openqa.selenium.TimeoutException: java.util.concurrent.TimeoutException
Build info: version: '4.15.0', revision: '1d14b5521b'
System info: os.name: 'Mac OS X', os.arch: 'x86_64', os.version: '14.0', java.version: '21.0.1'
Driver info: driver.version: MobileDeviceDriver
at org.openqa.selenium.remote.http.netty.NettyHttpHandler.makeCall(NettyHttpHandler.java:65)
at org.openqa.selenium.remote.http.AddSeleniumUserAgent.lambda$apply$0(AddSeleniumUserAgent.java:42)
at io.appium.java_client.remote.AppiumCommandExecutor.lambda$null$0(AppiumCommandExecutor.java:199)
at org.openqa.selenium.remote.http.Filter.lambda$andFinally$1(Filter.java:55)
at org.openqa.selenium.remote.http.netty.NettyHttpHandler.execute(NettyHttpHandler.java:48)
at org.openqa.selenium.remote.http.AddSeleniumUserAgent.lambda$apply$0(AddSeleniumUserAgent.java:42)
at io.appium.java_client.remote.AppiumCommandExecutor.lambda$null$0(AppiumCommandExecutor.java:199)
at org.openqa.selenium.remote.http.Filter.lambda$andFinally$1(Filter.java:55)
at org.openqa.selenium.remote.http.netty.NettyClient.execute(NettyClient.java:97)
at org.openqa.selenium.remote.ProtocolHandshake.createSession(ProtocolHandshake.java:115)
at java.base/jdk.internal.reflect.DirectMethodHandleAccessor.invoke(DirectMethodHandleAccessor.java:103)
... 37 more
Caused by: java.util.concurrent.TimeoutException
at java.base/java.util.concurrent.CompletableFuture.timedGet(CompletableFuture.java:1960)
at java.base/java.util.concurrent.CompletableFuture.get(CompletableFuture.java:2095)
at org.asynchttpclient.netty.NettyResponseFuture.get(NettyResponseFuture.java:206)
at org.openqa.selenium.remote.http.netty.NettyHttpHandler.makeCall(NettyHttpHandler.java:59)
... 47 more
]]>
    </error>
  </testcase> <!-- setUp -->
  <system-out/>
  <testcase classname="mobile_tests.PaymentTests" name="verify_user_making_payment" time="240.125">
    <failure message="Amount has not been deducted. did not expect [35000] but found [35000]" type="java.lang.AssertionError">
      <![CDATA[java.lang.AssertionError: Amount has not been deducted. did not expect [35000] but found [35000]
at org.testng.Assert.fail(Assert.java:99)
at org.testng.Assert.failEquals(Assert.java:1041)
at org.testng.Assert.assertNotEqualsImpl(Assert.java:147)
at org.testng.Assert.assertNotEquals(Assert.java:1531)
at mobile_tests.PaymentTests.verify_user_making_payment(PaymentTests.java:86)
at java.base/jdk.internal.reflect.DirectMethodHandleAccessor.invoke(DirectMethodHandleAccessor.java:103)
at java.base/java.lang.reflect.Method.invoke(Method.java:580)
at org.testng.internal.MethodInvocationHelper.invokeMethod(MethodInvocationHelper.java:133)
at org.testng.internal.TestInvoker.invokeMethod(TestInvoker.java:598)
at org.testng.internal.TestInvoker.invokeTestMethod(TestInvoker.java:173)
at org.testng.internal.MethodRunner.runInSequence(MethodRunner.java:46)
at org.testng.internal.TestInvoker$MethodInvocationAgent.invoke(TestInvoker.java:824)
at org.testng.internal.TestInvoker.invokeTestMethods(TestInvoker.java:146)
at org.testng.internal.TestMethodWorker.invokeTestMethods(TestMethodWorker.java:146)
at org.testng.internal.TestMethodWorker.run(TestMethodWorker.java:128)
at java.base/java.util.ArrayList.forEach(ArrayList.java:1596)
at org.testng.TestRunner.privateRun(TestRunner.java:794)
at org.testng.TestRunner.run(TestRunner.java:596)
at org.testng.SuiteRunner.runTest(SuiteRunner.java:377)
at org.testng.SuiteRunner.access$000(SuiteRunner.java:28)
at org.testng.SuiteRunner$SuiteWorker.run(SuiteRunner.java:418)
at org.testng.internal.thread.ThreadUtil.lambda$execute$0(ThreadUtil.java:64)
at java.base/java.util.concurrent.FutureTask.run(FutureTask.java:317)
at java.base/java.util.concurrent.ThreadPoolExecutor.runWorker(ThreadPoolExecutor.java:1144)
at java.base/java.util.concurrent.ThreadPoolExecutor$Worker.run(ThreadPoolExecutor.java:642)
at java.base/java.lang.Thread.run(Thread.java:1583)
]]>
    </failure>
  </testcase> <!-- verify_user_making_payment -->
  <system-out/>
  <testcase classname="mobile_tests.PaymentTests" name="verify_user_making_payment" time="242.729">
    <failure message="Amount has not been deducted. did not expect [35000] but found [35000]" type="java.lang.AssertionError">
      <![CDATA[java.lang.AssertionError: Amount has not been deducted. did not expect [35000] but found [35000]
at org.testng.Assert.fail(Assert.java:99)
at org.testng.Assert.failEquals(Assert.java:1041)
at org.testng.Assert.assertNotEqualsImpl(Assert.java:147)
at org.testng.Assert.assertNotEquals(Assert.java:1531)
at mobile_tests.PaymentTests.verify_user_making_payment(PaymentTests.java:86)
at java.base/jdk.internal.reflect.DirectMethodHandleAccessor.invoke(DirectMethodHandleAccessor.java:103)
at java.base/java.lang.reflect.Method.invoke(Method.java:580)
at org.testng.internal.MethodInvocationHelper.invokeMethod(MethodInvocationHelper.java:133)
at org.testng.internal.TestInvoker.invokeMethod(TestInvoker.java:598)
at org.testng.internal.TestInvoker.invokeTestMethod(TestInvoker.java:173)
at org.testng.internal.MethodRunner.runInSequence(MethodRunner.java:46)
at org.testng.internal.TestInvoker$MethodInvocationAgent.invoke(TestInvoker.java:824)
at org.testng.internal.TestInvoker.invokeTestMethods(TestInvoker.java:146)
at org.testng.internal.TestMethodWorker.invokeTestMethods(TestMethodWorker.java:146)
at org.testng.internal.TestMethodWorker.run(TestMethodWorker.java:128)
at java.base/java.util.ArrayList.forEach(ArrayList.java:1596)
at org.testng.TestRunner.privateRun(TestRunner.java:794)
at org.testng.TestRunner.run(TestRunner.java:596)
at org.testng.SuiteRunner.runTest(SuiteRunner.java:377)
at org.testng.SuiteRunner.access$000(SuiteRunner.java:28)
at org.testng.SuiteRunner$SuiteWorker.run(SuiteRunner.java:418)
at org.testng.internal.thread.ThreadUtil.lambda$execute$0(ThreadUtil.java:64)
at java.base/java.util.concurrent.FutureTask.run(FutureTask.java:317)
at java.base/java.util.concurrent.ThreadPoolExecutor.runWorker(ThreadPoolExecutor.java:1144)
at java.base/java.util.concurrent.ThreadPoolExecutor$Worker.run(ThreadPoolExecutor.java:642)
at java.base/java.lang.Thread.run(Thread.java:1583)
]]>
    </failure>
  </testcase> <!-- verify_user_making_payment -->
  <system-out/>
  <testcase classname="mobile_tests.PaymentTests" name="tearDown" time="0.001">
    <error message="Cannot invoke &quot;org.openqa.selenium.remote.RemoteWebDriver.quit()&quot; because the return value of &quot;base.MobileDeviceDriver.getDriver()&quot; is null" type="java.lang.NullPointerException">
      <![CDATA[java.lang.NullPointerException: Cannot invoke "org.openqa.selenium.remote.RemoteWebDriver.quit()" because the return value of "base.MobileDeviceDriver.getDriver()" is null
at base.MobileDeviceDriver.tearDown(MobileDeviceDriver.java:82)
at java.base/jdk.internal.reflect.DirectMethodHandleAccessor.invoke(DirectMethodHandleAccessor.java:103)
at java.base/java.lang.reflect.Method.invoke(Method.java:580)
at org.testng.internal.MethodInvocationHelper.invokeMethod(MethodInvocationHelper.java:133)
at org.testng.internal.MethodInvocationHelper.invokeMethodConsideringTimeout(MethodInvocationHelper.java:62)
at org.testng.internal.ConfigInvoker.invokeConfigurationMethod(ConfigInvoker.java:385)
at org.testng.internal.ConfigInvoker.invokeConfigurations(ConfigInvoker.java:321)
at org.testng.internal.TestInvoker.runConfigMethods(TestInvoker.java:700)
at org.testng.internal.TestInvoker.runAfterGroupsConfigurations(TestInvoker.java:676)
at org.testng.internal.TestInvoker.invokeMethod(TestInvoker.java:546)
at org.testng.internal.TestInvoker.invokeTestMethod(TestInvoker.java:173)
at org.testng.internal.MethodRunner.runInSequence(MethodRunner.java:46)
at org.testng.internal.TestInvoker$MethodInvocationAgent.invoke(TestInvoker.java:824)
at org.testng.internal.TestInvoker.invokeTestMethods(TestInvoker.java:146)
at org.testng.internal.TestMethodWorker.invokeTestMethods(TestMethodWorker.java:146)
at org.testng.internal.TestMethodWorker.run(TestMethodWorker.java:128)
at java.base/java.util.ArrayList.forEach(ArrayList.java:1596)
at org.testng.TestRunner.privateRun(TestRunner.java:794)
at org.testng.TestRunner.run(TestRunner.java:596)
at org.testng.SuiteRunner.runTest(SuiteRunner.java:377)
at org.testng.SuiteRunner.access$000(SuiteRunner.java:28)
at org.testng.SuiteRunner$SuiteWorker.run(SuiteRunner.java:418)
at org.testng.internal.thread.ThreadUtil.lambda$execute$0(ThreadUtil.java:64)
at java.base/java.util.concurrent.FutureTask.run(FutureTask.java:317)
at java.base/java.util.concurrent.ThreadPoolExecutor.runWorker(ThreadPoolExecutor.java:1144)
at java.base/java.util.concurrent.ThreadPoolExecutor$Worker.run(ThreadPoolExecutor.java:642)
at java.base/java.lang.Thread.run(Thread.java:1583)
]]>
    </error>
  </testcase> <!-- tearDown -->
  <system-out/>
  <testcase classname="mobile_tests.PaymentTests" name="verify_user_making_payment" time="62.381"/>
  <system-out/>
</testsuite> <!-- mobile_tests.PaymentTests -->
